Workbook

Sheet Dashboard
A1: Metformin CGM Efficacy Dashboard
A2: Investor-facing readout updates when participant exports are linked or pasted.
A4: Included Participants | C4: Mean Glucose Reduction | E4: TIR Gain | G4: Hyper AUC Reduction | I4: Responder Rate | K4: Composite Score
A5: =Cohort_Stats!D5 | C5: =Cohort_Stats!E5 | E5: =Cohort_Stats!E6 | G5: =Cohort_Stats!E7 | I5: =IFERROR(AVERAGE(FILTER('Participant_Metrics'!$CM$6:$CM$35,'Participant_Metrics'!$BX$6:$BX$35=1)),"") | K5: =Cohort_Stats!E15
A9: Chart Data
A10: Metric | B10: All Active | C10: Once Daily | D10: Twice Daily
A11: Mean Glucose Reduction | B11: =Cohort_Stats!E5 | C11: =Cohort_Stats!L5 | D11: =Cohort_Stats!N5
A12: TIR Gain | B12: =Cohort_Stats!E6 | C12: =Cohort_Stats!L6 | D12: =Cohort_Stats!N6
A13: Hyper AUC Reduction % | B13: =Cohort_Stats!E7 | C13: =Cohort_Stats!L7 | D13: =Cohort_Stats!N7
A14: Fasting 6-9 AM Reduction | B14: =Cohort_Stats!E10 | C14: =Cohort_Stats!L10 | D14: =Cohort_Stats!N10
A15: GRI Reduction | B15: =Cohort_Stats!E13 | C15: =Cohort_Stats!L13 | D15: =Cohort_Stats!N13
A16: Composite Efficacy Score | B16: =Cohort_Stats!E15 | C16: =Cohort_Stats!L15 | D16: =Cohort_Stats!N15
A18: Tolerability & Weight (self-reported daily log)
A19: Weight Change (lb) | C19: Weight Change % | E19: Avg Taste (1-5) | G19: Avg Aftertaste (1-5) | I19: Dose-Time SD (min)
A20: =Cohort_Stats!E16 | C20: =Cohort_Stats!E17 | E20: =Cohort_Stats!E18 | G20: =Cohort_Stats!E19 | I20: =IFERROR(AVERAGE(FILTER('Participant_Metrics'!$CU$6:$CU$35,'Participant_Metrics'!$BX$6:$BX$35=1)),"")
A30: Interpretation Guardrails
A31: Best investor signal: consistent within-participant reductions in mean glucose, hyperglycemic AUC, HBGI/GRI, and fasting or dawn blocks.
A32: Dose response: Twice Daily should show larger average improvement than Once Daily without increasing hypoglycemia burden.
A33: Do not overclaim: this workbook supports an exploratory efficacy story; final claims need protocol lock, adherence data, and statistical review.

Sheet Study_Setup
A1: Metformin CGM Study - Setup and Assumptions
A2: Topic | B2: Current workbook assumption
A3: Study design | B3: Within-participant baseline: week 1 off metformin, week 2 onward on assigned metformin regimen.
A4: Dose arms | B4: Once Daily and Twice Daily. Fill each participant workbook INPUT!I4 before export.
A5: Primary efficacy endpoint | B5: Mean Glucose Reduction and Daily Hyper AUC Reduction from Off Meds to On Meds.
A6: Secondary endpoints | B6: TIR Gain, GMI Reduction, HBGI Reduction, GRI Reduction, fasting/dawn block reductions, responder rate.
A7: Safety watch | B7: No increase in hypoglycemic AUC or time below range. Review participants with increased hypo burden.
A8: File intake | B8: Automatic links expect P001_LingoCGM_CGM_Report_FIXED.xlsx through P030_LingoCGM_CGM_Report_FIXED.xlsx in the same folder as this workbook.
A9: Manual fallback | B9: Open each participant workbook, copy Study Export row 3, and paste values into Pasted_Exports rows 6-35.
A12: Editable thresholds
A13: Threshold | B13: Value | C13: Unit / note
A14: Minimum Off Days | B14: 5 | C14: days
A15: Minimum On Days | B15: 7 | C15: days
A16: Mean glucose responder threshold | B16: 10 | C16: mg/dL reduction
A17: TIR responder threshold | B17: 5 | C17: percentage point gain
A18: Hyper AUC responder threshold | B18: 0.2 | C18: fractional reduction
A19: Hypo AUC tolerance | B19: 0 | C19: mg/dL-hr/day increase allowed
A20: Alpha | B20: 0.05 | C20: two-sided
A21: Power planning target | B21: 0.8 | C21: fraction
A22: Expected paired SD of mean-glucose change | B22: 18 | C22: mg/dL
A23: Planned participants | B23: 30 | C23: count
A26: Quick power sanity check
A27: Planning calculation | B27: Value | C27: Note
A28: Approx. detectable paired mean-glucose reduction | B28: =IFERROR((NORM.S.INV(1-$B$20/2)+NORM.S.INV($B$21))*$B$22/SQRT($B$23),"") | C28: mg/dL, normal approximation
A29: Participants needed for 10 mg/dL paired reduction | B29: =IFERROR(ROUNDUP(((NORM.S.INV(1-$B$20/2)+NORM.S.INV($B$21))*$B$22/$B$16)^2,0),"") | C29: using responder threshold as effect

Sheet Source_Files
A1: Expected Participant Source Files
A3: Place renamed participant files in the same folder as this workbook for automatic links, or paste Study Export rows into Pasted_Exports.
A5: Participant Slot | B5: Expected File Name | C5: Treatment Arm | D5: Participant ID | E5: Status
A6: P001 | B6: P001_LingoCGM_CGM_Report_FIXED.xlsx | D6: ='Participant_Metrics'!A6 | E6: =IF('Participant_Metrics'!A6<>"","Loaded / pasted","Waiting for file or paste")
A7: P002 | B7: P002_LingoCGM_CGM_Report_FIXED.xlsx | D7: ='Participant_Metrics'!A7 | E7: =IF('Participant_Metrics'!A7<>"","Loaded / pasted","Waiting for file or paste")
A8: P003 | B8: P003_LingoCGM_CGM_Report_FIXED.xlsx | D8: ='Participant_Metrics'!A8 | E8: =IF('Participant_Metrics'!A8<>"","Loaded / pasted","Waiting for file or paste")
A9: P004 | B9: P004_LingoCGM_CGM_Report_FIXED.xlsx | D9: ='Participant_Metrics'!A9 | E9: =IF('Participant_Metrics'!A9<>"","Loaded / pasted","Waiting for file or paste")
A10: P005 | B10: P005_LingoCGM_CGM_Report_FIXED.xlsx | D10: ='Participant_Metrics'!A10 | E10: =IF('Participant_Metrics'!A10<>"","Loaded / pasted","Waiting for file or paste")
A11: P006 | B11: P006_LingoCGM_CGM_Report_FIXED.xlsx | D11: ='Participant_Metrics'!A11 | E11: =IF('Participant_Metrics'!A11<>"","Loaded / pasted","Waiting for file or paste")
A12: P007 | B12: P007_LingoCGM_CGM_Report_FIXED.xlsx | D12: ='Participant_Metrics'!A12 | E12: =IF('Participant_Metrics'!A12<>"","Loaded / pasted","Waiting for file or paste")
A13: P008 | B13: P008_LingoCGM_CGM_Report_FIXED.xlsx | D13: ='Participant_Metrics'!A13 | E13: =IF('Participant_Metrics'!A13<>"","Loaded / pasted","Waiting for file or paste")
A14: P009 | B14: P009_LingoCGM_CGM_Report_FIXED.xlsx | D14: ='Participant_Metrics'!A14 | E14: =IF('Participant_Metrics'!A14<>"","Loaded / pasted","Waiting for file or paste")
A15: P010 | B15: P010_LingoCGM_CGM_Report_FIXED.xlsx | D15: ='Participant_Metrics'!A15 | E15: =IF('Participant_Metrics'!A15<>"","Loaded / pasted","Waiting for file or paste")
A16: P011 | B16: P011_LingoCGM_CGM_Report_FIXED.xlsx | D16: ='Participant_Metrics'!A16 | E16: =IF('Participant_Metrics'!A16<>"","Loaded / pasted","Waiting for file or paste")
A17: P012 | B17: P012_LingoCGM_CGM_Report_FIXED.xlsx | D17: ='Participant_Metrics'!A17 | E17: =IF('Participant_Metrics'!A17<>"","Loaded / pasted","Waiting for file or paste")
... A35: P030 | B35: P030_LingoCGM_CGM_Report_FIXED.xlsx | D35: ='Participant_Metrics'!A35 | E35: =IF('Participant_Metrics'!A35<>"","Loaded / pasted","Waiting for file or paste")

Sheet File_Intake
A1: Automatic File Intake - external links to Study Export
A3: Expected filenames are listed on Source_Files. If Excel asks to update links, allow it after all 30 files are in the same folder.
A5: Participant ID | B5: Treatment Arm | C5: Dose Detail | D5: Source Workbook | E5: Metformin Start Date | F5: Washout Days | G5: Total Readings | H5: Total Days | I5: Off Readings | J5: On Readings | K5: Off Days | L5: On Days | M5: Avg Glucose Off | N5: Avg Glucose On | O5: Avg Glucose Delta | P5: GMI Off | Q5: GMI On | R5: GMI Delta | S5: TIR Off | T5: TIR On | U5: TIR Delta | V5: TBR L2 Off | W5: TBR L2 On | X5: TBR L2 Delta | Y5: TBR L1 Off | Z5: TBR L1 On | AA5: TBR L1 Delta | AB5: TAR L1 Off | AC5: TAR L1 On | AD5: TAR L1 Delta | AE5: TAR L2 Off | AF5: TAR L2 On | AG5: TAR L2 Delta | AH5: Daily Hyper AUC Off | AI5: Daily Hyper AUC On | AJ5: Daily Hyper AUC Delta | AK5: Daily Hypo AUC Off | AL5: Daily Hypo AUC On | AM5: Daily Hypo AUC Delta | AN5: LBGI Off | AO5: LBGI On | AP5: LBGI Delta | AQ5: HBGI Off | AR5: HBGI On | AS5: HBGI Delta | AT5: SD Off | AU5: SD On | AV5: SD Delta | AW5: CV Off | AX5: CV On | AY5: CV Delta | AZ5: MODD Off | BA5: MODD On | BB5: MODD Delta | BC5: M Value Off | BD5: M Value On | BE5: M Value Delta | BF5: GRI Off | BG5: GRI On | BH5: GRI Delta | BI5: 12-3 AM Off | BJ5: 12-3 AM On | BK5: 12-3 AM Delta | BL5: 3-6 AM Off | BM5: 3-6 AM On | BN5: 3-6 AM Delta | BO5: 6-9 AM Off | BP5: 6-9 AM On | BQ5: 6-9 AM Delta | BR5: Median Off | BS5: Median On | BT5: Median Delta | BU5: P90 Off | BV5: P90 On | BW5: P90 Delta | BX5: Days Logged | BY5: Avg Weight Off (lb) | BZ5: Avg Weight On (lb) | CA5: Weight Change (lb) | CB5: Weight Change % | CC5: Avg Dose Time (On) | CD5: Dose Time SD (min) | CE5: Dose-Time Days (On) | CF5: Avg Taste (1-5) | CG5: Avg Aftertaste (1-5) | CH5: Taste Days Logged
A6: =IFERROR('[P001_LingoCGM_CGM_Report_FIXED.xlsx]Study Export'!A$3,"") | B6: =IFERROR('[P001_LingoCGM_CGM_Report_FIXED.xlsx]Study Export'!B$3,"") | C6: =IFERROR('[P001_LingoCGM_CGM_Report_FIXED.xlsx]Study Export'!C$3,"") | D6: =IFERROR('[P001_LingoCGM_CGM_Report_FIXED.xlsx]Study Export'!D$3,"") | E6: =IFERROR('[P001_LingoCGM_CGM_Report_FIXED.xlsx]Study Export'!E$3,"") | F6: =IFERROR('[P001_LingoCGM_CGM_Report_FIXED.xlsx]Study Export'!F$3,"") | G6: =IFERROR('[P001_LingoCGM_CGM_Report_FIXED.xlsx]Study Export'!G$3,"") | H6: =IFERROR('[P001_LingoCGM_CGM_Report_FIXED.xlsx]Study Export'!H$3,"") | ... CH6: =IFERROR('[P001_LingoCGM_CGM_Report_FIXED.xlsx]Study Export'!CH$3,"")
A7: =IFERROR('[P002_LingoCGM_CGM_Report_FIXED.xlsx]Study Export'!A$3,"") | B7: =IFERROR('[P002_LingoCGM_CGM_Report_FIXED.xlsx]Study Export'!B$3,"") | C7: =IFERROR('[P002_LingoCGM_CGM_Report_FIXED.xlsx]Study Export'!C$3,"") | D7: =IFERROR('[P002_LingoCGM_CGM_Report_FIXED.xlsx]Study Export'!D$3,"") | E7: =IFERROR('[P002_LingoCGM_CGM_Report_FIXED.xlsx]Study Export'!E$3,"") | F7: =IFERROR('[P002_LingoCGM_CGM_Report_FIXED.xlsx]Study Export'!F$3,"") | G7: =IFERROR('[P002_LingoCGM_CGM_Report_FIXED.xlsx]Study Export'!G$3,"") | H7: =IFERROR('[P002_LingoCGM_CGM_Report_FIXED.xlsx]Study Export'!H$3,"") | ... CH7: =IFERROR('[P002_LingoCGM_CGM_Report_FIXED.xlsx]Study Export'!CH$3,"")
A8: =IFERROR('[P003_LingoCGM_CGM_Report_FIXED.xlsx]Study Export'!A$3,"") | B8: =IFERROR('[P003_LingoCGM_CGM_Report_FIXED.xlsx]Study Export'!B$3,"") | C8: =IFERROR('[P003_LingoCGM_CGM_Report_FIXED.xlsx]Study Export'!C$3,"") | D8: =IFERROR('[P003_LingoCGM_CGM_Report_FIXED.xlsx]Study Export'!D$3,"") | E8: =IFERROR('[P003_LingoCGM_CGM_Report_FIXED.xlsx]Study Export'!E$3,"") | F8: =IFERROR('[P003_LingoCGM_CGM_Report_FIXED.xlsx]Study Export'!F$3,"") | G8: =IFERROR('[P003_LingoCGM_CGM_Report_FIXED.xlsx]Study Export'!G$3,"") | H8: =IFERROR('[P003_LingoCGM_CGM_Report_FIXED.xlsx]Study Export'!H$3,"") | ... CH8: =IFERROR('[P003_LingoCGM_CGM_Report_FIXED.xlsx]Study Export'!CH$3,"")
A9: =IFERROR('[P004_LingoCGM_CGM_Report_FIXED.xlsx]Study Export'!A$3,"") | B9: =IFERROR('[P004_LingoCGM_CGM_Report_FIXED.xlsx]Study Export'!B$3,"") | C9: =IFERROR('[P004_LingoCGM_CGM_Report_FIXED.xlsx]Study Export'!C$3,"") | D9: =IFERROR('[P004_LingoCGM_CGM_Report_FIXED.xlsx]Study Export'!D$3,"") | E9: =IFERROR('[P004_LingoCGM_CGM_Report_FIXED.xlsx]Study Export'!E$3,"") | F9: =IFERROR('[P004_LingoCGM_CGM_Report_FIXED.xlsx]Study Export'!F$3,"") | G9: =IFERROR('[P004_LingoCGM_CGM_Report_FIXED.xlsx]Study Export'!G$3,"") | H9: =IFERROR('[P004_LingoCGM_CGM_Report_FIXED.xlsx]Study Export'!H$3,"") | ... CH9: =IFERROR('[P004_LingoCGM_CGM_Report_FIXED.xlsx]Study Export'!CH$3,"")
A10: =IFERROR('[P005_LingoCGM_CGM_Report_FIXED.xlsx]Study Export'!A$3,"") | B10: =IFERROR('[P005_LingoCGM_CGM_Report_FIXED.xlsx]Study Export'!B$3,"") | C10: =IFERROR('[P005_LingoCGM_CGM_Report_FIXED.xlsx]Study Export'!C$3,"") | D10: =IFERROR('[P005_LingoCGM_CGM_Report_FIXED.xlsx]Study Export'!D$3,"") | E10: =IFERROR('[P005_LingoCGM_CGM_Report_FIXED.xlsx]Study Export'!E$3,"") | F10: =IFERROR('[P005_LingoCGM_CGM_Report_FIXED.xlsx]Study Export'!F$3,"") | G10: =IFERROR('[P005_LingoCGM_CGM_Report_FIXED.xlsx]Study Export'!G$3,"") | H10: =IFERROR('[P005_LingoCGM_CGM_Report_FIXED.xlsx]Study Export'!H$3,"") | ... CH10: =IFERROR('[P005_LingoCGM_CGM_Report_FIXED.xlsx]Study Export'!CH$3,"")
A11: =IFERROR('[P006_LingoCGM_CGM_Report_FIXED.xlsx]Study Export'!A$3,"") | B11: =IFERROR('[P006_LingoCGM_CGM_Report_FIXED.xlsx]Study Export'!B$3,"") | C11: =IFERROR('[P006_LingoCGM_CGM_Report_FIXED.xlsx]Study Export'!C$3,"") | D11: =IFERROR('[P006_LingoCGM_CGM_Report_FIXED.xlsx]Study Export'!D$3,"") | E11: =IFERROR('[P006_LingoCGM_CGM_Report_FIXED.xlsx]Study Export'!E$3,"") | F11: =IFERROR('[P006_LingoCGM_CGM_Report_FIXED.xlsx]Study Export'!F$3,"") | G11: =IFERROR('[P006_LingoCGM_CGM_Report_FIXED.xlsx]Study Export'!G$3,"") | H11: =IFERROR('[P006_LingoCGM_CGM_Report_FIXED.xlsx]Study Export'!H$3,"") | ... CH11: =IFERROR('[P006_LingoCGM_CGM_Report_FIXED.xlsx]Study Export'!CH$3,"")
A12: =IFERROR('[P007_LingoCGM_CGM_Report_FIXED.xlsx]Study Export'!A$3,"") | B12: =IFERROR('[P007_LingoCGM_CGM_Report_FIXED.xlsx]Study Export'!B$3,"") | C12: =IFERROR('[P007_LingoCGM_CGM_Report_FIXED.xlsx]Study Export'!C$3,"") | D12: =IFERROR('[P007_LingoCGM_CGM_Report_FIXED.xlsx]Study Export'!D$3,"") | E12: =IFERROR('[P007_LingoCGM_CGM_Report_FIXED.xlsx]Study Export'!E$3,"") | F12: =IFERROR('[P007_LingoCGM_CGM_Report_FIXED.xlsx]Study Export'!F$3,"") | G12: =IFERROR('[P007_LingoCGM_CGM_Report_FIXED.xlsx]Study Export'!G$3,"") | H12: =IFERROR('[P007_LingoCGM_CGM_Report_FIXED.xlsx]Study Export'!H$3,"") | ... CH12: =IFERROR('[P007_LingoCGM_CGM_Report_FIXED.xlsx]Study Export'!CH$3,"")
A13: =IFERROR('[P008_LingoCGM_CGM_Report_FIXED.xlsx]Study Export'!A$3,"") | B13: =IFERROR('[P008_LingoCGM_CGM_Report_FIXED.xlsx]Study Export'!B$3,"") | C13: =IFERROR('[P008_LingoCGM_CGM_Report_FIXED.xlsx]Study Export'!C$3,"") | D13: =IFERROR('[P008_LingoCGM_CGM_Report_FIXED.xlsx]Study Export'!D$3,"") | E13: =IFERROR('[P008_LingoCGM_CGM_Report_FIXED.xlsx]Study Export'!E$3,"") | F13: =IFERROR('[P008_LingoCGM_CGM_Report_FIXED.xlsx]Study Export'!F$3,"") | G13: =IFERROR('[P008_LingoCGM_CGM_Report_FIXED.xlsx]Study Export'!G$3,"") | H13: =IFERROR('[P008_LingoCGM_CGM_Report_FIXED.xlsx]Study Export'!H$3,"") | ... CH13: =IFERROR('[P008_LingoCGM_CGM_Report_FIXED.xlsx]Study Export'!CH$3,"")
A14: =IFERROR('[P009_LingoCGM_CGM_Report_FIXED.xlsx]Study Export'!A$3,"") | B14: =IFERROR('[P009_LingoCGM_CGM_Report_FIXED.xlsx]Study Export'!B$3,"") | C14: =IFERROR('[P009_LingoCGM_CGM_Report_FIXED.xlsx]Study Export'!C$3,"") | D14: =IFERROR('[P009_LingoCGM_CGM_Report_FIXED.xlsx]Study Export'!D$3,"") | E14: =IFERROR('[P009_LingoCGM_CGM_Report_FIXED.xlsx]Study Export'!E$3,"") | F14: =IFERROR('[P009_LingoCGM_CGM_Report_FIXED.xlsx]Study Export'!F$3,"") | G14: =IFERROR('[P009_LingoCGM_CGM_Report_FIXED.xlsx]Study Export'!G$3,"") | H14: =IFERROR('[P009_LingoCGM_CGM_Report_FIXED.xlsx]Study Export'!H$3,"") | ... CH14: =IFERROR('[P009_LingoCGM_CGM_Report_FIXED.xlsx]Study Export'!CH$3,"")
A15: =IFERROR('[P010_LingoCGM_CGM_Report_FIXED.xlsx]Study Export'!A$3,"") | B15: =IFERROR('[P010_LingoCGM_CGM_Report_FIXED.xlsx]Study Export'!B$3,"") | C15: =IFERROR('[P010_LingoCGM_CGM_Report_FIXED.xlsx]Study Export'!C$3,"") | D15: =IFERROR('[P010_LingoCGM_CGM_Report_FIXED.xlsx]Study Export'!D$3,"") | E15: =IFERROR('[P010_LingoCGM_CGM_Report_FIXED.xlsx]Study Export'!E$3,"") | F15: =IFERROR('[P010_LingoCGM_CGM_Report_FIXED.xlsx]Study Export'!F$3,"") | G15: =IFERROR('[P010_LingoCGM_CGM_Report_FIXED.xlsx]Study Export'!G$3,"") | H15: =IFERROR('[P010_LingoCGM_CGM_Report_FIXED.xlsx]Study Export'!H$3,"") | ... CH15: =IFERROR('[P010_LingoCGM_CGM_Report_FIXED.xlsx]Study Export'!CH$3,"")
A16: =IFERROR('[P011_LingoCGM_CGM_Report_FIXED.xlsx]Study Export'!A$3,"") | B16: =IFERROR('[P011_LingoCGM_CGM_Report_FIXED.xlsx]Study Export'!B$3,"") | C16: =IFERROR('[P011_LingoCGM_CGM_Report_FIXED.xlsx]Study Export'!C$3,"") | D16: =IFERROR('[P011_LingoCGM_CGM_Report_FIXED.xlsx]Study Export'!D$3,"") | E16: =IFERROR('[P011_LingoCGM_CGM_Report_FIXED.xlsx]Study Export'!E$3,"") | F16: =IFERROR('[P011_LingoCGM_CGM_Report_FIXED.xlsx]Study Export'!F$3,"") | G16: =IFERROR('[P011_LingoCGM_CGM_Report_FIXED.xlsx]Study Export'!G$3,"") | H16: =IFERROR('[P011_LingoCGM_CGM_Report_FIXED.xlsx]Study Export'!H$3,"") | ... CH16: =IFERROR('[P011_LingoCGM_CGM_Report_FIXED.xlsx]Study Export'!CH$3,"")
A17: =IFERROR('[P012_LingoCGM_CGM_Report_FIXED.xlsx]Study Export'!A$3,"") | B17: =IFERROR('[P012_LingoCGM_CGM_Report_FIXED.xlsx]Study Export'!B$3,"") | C17: =IFERROR('[P012_LingoCGM_CGM_Report_FIXED.xlsx]Study Export'!C$3,"") | D17: =IFERROR('[P012_LingoCGM_CGM_Report_FIXED.xlsx]Study Export'!D$3,"") | E17: =IFERROR('[P012_LingoCGM_CGM_Report_FIXED.xlsx]Study Export'!E$3,"") | F17: =IFERROR('[P012_LingoCGM_CGM_Report_FIXED.xlsx]Study Export'!F$3,"") | G17: =IFERROR('[P012_LingoCGM_CGM_Report_FIXED.xlsx]Study Export'!G$3,"") | H17: =IFERROR('[P012_LingoCGM_CGM_Report_FIXED.xlsx]Study Export'!H$3,"") | ... CH17: =IFERROR('[P012_LingoCGM_CGM_Report_FIXED.xlsx]Study Export'!CH$3,"")
A18: =IFERROR('[P013_LingoCGM_CGM_Report_FIXED.xlsx]Study Export'!A$3,"") | B18: =IFERROR('[P013_LingoCGM_CGM_Report_FIXED.xlsx]Study Export'!B$3,"") | C18: =IFERROR('[P013_LingoCGM_CGM_Report_FIXED.xlsx]Study Export'!C$3,"") | D18: =IFERROR('[P013_LingoCGM_CGM_Report_FIXED.xlsx]Study Export'!D$3,"") | E18: =IFERROR('[P013_LingoCGM_CGM_Report_FIXED.xlsx]Study Export'!E$3,"") | F18: =IFERROR('[P013_LingoCGM_CGM_Report_FIXED.xlsx]Study Export'!F$3,"") | G18: =IFERROR('[P013_LingoCGM_CGM_Report_FIXED.xlsx]Study Export'!G$3,"") | H18: =IFERROR('[P013_LingoCGM_CGM_Report_FIXED.xlsx]Study Export'!H$3,"") | ... CH18: =IFERROR('[P013_LingoCGM_CGM_Report_FIXED.xlsx]Study Export'!CH$3,"")
A19: =IFERROR('[P014_LingoCGM_CGM_Report_FIXED.xlsx]Study Export'!A$3,"") | B19: =IFERROR('[P014_LingoCGM_CGM_Report_FIXED.xlsx]Study Export'!B$3,"") | C19: =IFERROR('[P014_LingoCGM_CGM_Report_FIXED.xlsx]Study Export'!C$3,"") | D19: =IFERROR('[P014_LingoCGM_CGM_Report_FIXED.xlsx]Study Export'!D$3,"") | E19: =IFERROR('[P014_LingoCGM_CGM_Report_FIXED.xlsx]Study Export'!E$3,"") | F19: =IFERROR('[P014_LingoCGM_CGM_Report_FIXED.xlsx]Study Export'!F$3,"") | G19: =IFERROR('[P014_LingoCGM_CGM_Report_FIXED.xlsx]Study Export'!G$3,"") | H19: =IFERROR('[P014_LingoCGM_CGM_Report_FIXED.xlsx]Study Export'!H$3,"") | ... CH19: =IFERROR('[P014_LingoCGM_CGM_Report_FIXED.xlsx]Study Export'!CH$3,"")
A20: =IFERROR('[P015_LingoCGM_CGM_Report_FIXED.xlsx]Study Export'!A$3,"") | B20: =IFERROR('[P015_LingoCGM_CGM_Report_FIXED.xlsx]Study Export'!B$3,"") | C20: =IFERROR('[P015_LingoCGM_CGM_Report_FIXED.xlsx]Study Export'!C$3,"") | D20: =IFERROR('[P015_LingoCGM_CGM_Report_FIXED.xlsx]Study Export'!D$3,"") | E20: =IFERROR('[P015_LingoCGM_CGM_Report_FIXED.xlsx]Study Export'!E$3,"") | F20: =IFERROR('[P015_LingoCGM_CGM_Report_FIXED.xlsx]Study Export'!F$3,"") | G20: =IFERROR('[P015_LingoCGM_CGM_Report_FIXED.xlsx]Study Export'!G$3,"") | H20: =IFERROR('[P015_LingoCGM_CGM_Report_FIXED.xlsx]Study Export'!H$3,"") | ... CH20: =IFERROR('[P015_LingoCGM_CGM_Report_FIXED.xlsx]Study Export'!CH$3,"")
A21: =IFERROR('[P016_LingoCGM_CGM_Report_FIXED.xlsx]Study Export'!A$3,"") | B21: =IFERROR('[P016_LingoCGM_CGM_Report_FIXED.xlsx]Study Export'!B$3,"") | C21: =IFERROR('[P016_LingoCGM_CGM_Report_FIXED.xlsx]Study Export'!C$3,"") | D21: =IFERROR('[P016_LingoCGM_CGM_Report_FIXED.xlsx]Study Export'!D$3,"") | E21: =IFERROR('[P016_LingoCGM_CGM_Report_FIXED.xlsx]Study Export'!E$3,"") | F21: =IFERROR('[P016_LingoCGM_CGM_Report_FIXED.xlsx]Study Export'!F$3,"") | G21: =IFERROR('[P016_LingoCGM_CGM_Report_FIXED.xlsx]Study Export'!G$3,"") | H21: =IFERROR('[P016_LingoCGM_CGM_Report_FIXED.xlsx]Study Export'!H$3,"") | ... CH21: =IFERROR('[P016_LingoCGM_CGM_Report_FIXED.xlsx]Study Export'!CH$3,"")
A22: =IFERROR('[P017_LingoCGM_CGM_Report_FIXED.xlsx]Study Export'!A$3,"") | B22: =IFERROR('[P017_LingoCGM_CGM_Report_FIXED.xlsx]Study Export'!B$3,"") | C22: =IFERROR('[P017_LingoCGM_CGM_Report_FIXED.xlsx]Study Export'!C$3,"") | D22: =IFERROR('[P017_LingoCGM_CGM_Report_FIXED.xlsx]Study Export'!D$3,"") | E22: =IFERROR('[P017_LingoCGM_CGM_Report_FIXED.xlsx]Study Export'!E$3,"") | F22: =IFERROR('[P017_LingoCGM_CGM_Report_FIXED.xlsx]Study Export'!F$3,"") | G22: =IFERROR('[P017_LingoCGM_CGM_Report_FIXED.xlsx]Study Export'!G$3,"") | H22: =IFERROR('[P017_LingoCGM_CGM_Report_FIXED.xlsx]Study Export'!H$3,"") | ... CH22: =IFERROR('[P017_LingoCGM_CGM_Report_FIXED.xlsx]Study Export'!CH$3,"")
A23: =IFERROR('[P018_LingoCGM_CGM_Report_FIXED.xlsx]Study Export'!A$3,"") | B23: =IFERROR('[P018_LingoCGM_CGM_Report_FIXED.xlsx]Study Export'!B$3,"") | C23: =IFERROR('[P018_LingoCGM_CGM_Report_FIXED.xlsx]Study Export'!C$3,"") | D23: =IFERROR('[P018_LingoCGM_CGM_Report_FIXED.xlsx]Study Export'!D$3,"") | E23: =IFERROR('[P018_LingoCGM_CGM_Report_FIXED.xlsx]Study Export'!E$3,"") | F23: =IFERROR('[P018_LingoCGM_CGM_Report_FIXED.xlsx]Study Export'!F$3,"") | G23: =IFERROR('[P018_LingoCGM_CGM_Report_FIXED.xlsx]Study Export'!G$3,"") | H23: =IFERROR('[P018_LingoCGM_CGM_Report_FIXED.xlsx]Study Export'!H$3,"") | ... CH23: =IFERROR('[P018_LingoCGM_CGM_Report_FIXED.xlsx]Study Export'!CH$3,"")
A24: =IFERROR('[P019_LingoCGM_CGM_Report_FIXED.xlsx]Study Export'!A$3,"") | B24: =IFERROR('[P019_LingoCGM_CGM_Report_FIXED.xlsx]Study Export'!B$3,"") | C24: =IFERROR('[P019_LingoCGM_CGM_Report_FIXED.xlsx]Study Export'!C$3,"") | D24: =IFERROR('[P019_LingoCGM_CGM_Report_FIXED.xlsx]Study Export'!D$3,"") | E24: =IFERROR('[P019_LingoCGM_CGM_Report_FIXED.xlsx]Study Export'!E$3,"") | F24: =IFERROR('[P019_LingoCGM_CGM_Report_FIXED.xlsx]Study Export'!F$3,"") | G24: =IFERROR('[P019_LingoCGM_CGM_Report_FIXED.xlsx]Study Export'!G$3,"") | H24: =IFERROR('[P019_LingoCGM_CGM_Report_FIXED.xlsx]Study Export'!H$3,"") | ... CH24: =IFERROR('[P019_LingoCGM_CGM_Report_FIXED.xlsx]Study Export'!CH$3,"")
A25: =IFERROR('[P020_LingoCGM_CGM_Report_FIXED.xlsx]Study Export'!A$3,"") | B25: =IFERROR('[P020_LingoCGM_CGM_Report_FIXED.xlsx]Study Export'!B$3,"") | C25: =IFERROR('[P020_LingoCGM_CGM_Report_FIXED.xlsx]Study Export'!C$3,"") | D25: =IFERROR('[P020_LingoCGM_CGM_Report_FIXED.xlsx]Study Export'!D$3,"") | E25: =IFERROR('[P020_LingoCGM_CGM_Report_FIXED.xlsx]Study Export'!E$3,"") | F25: =IFERROR('[P020_LingoCGM_CGM_Report_FIXED.xlsx]Study Export'!F$3,"") | G25: =IFERROR('[P020_LingoCGM_CGM_Report_FIXED.xlsx]Study Export'!G$3,"") | H25: =IFERROR('[P020_LingoCGM_CGM_Report_FIXED.xlsx]Study Export'!H$3,"") | ... CH25: =IFERROR('[P020_LingoCGM_CGM_Report_FIXED.xlsx]Study Export'!CH$3,"")
A26: =IFERROR('[P021_LingoCGM_CGM_Report_FIXED.xlsx]Study Export'!A$3,"") | B26: =IFERROR('[P021_LingoCGM_CGM_Report_FIXED.xlsx]Study Export'!B$3,"") | C26: =IFERROR('[P021_LingoCGM_CGM_Report_FIXED.xlsx]Study Export'!C$3,"") | D26: =IFERROR('[P021_LingoCGM_CGM_Report_FIXED.xlsx]Study Export'!D$3,"") | E26: =IFERROR('[P021_LingoCGM_CGM_Report_FIXED.xlsx]Study Export'!E$3,"") | F26: =IFERROR('[P021_LingoCGM_CGM_Report_FIXED.xlsx]Study Export'!F$3,"") | G26: =IFERROR('[P021_LingoCGM_CGM_Report_FIXED.xlsx]Study Export'!G$3,"") | H26: =IFERROR('[P021_LingoCGM_CGM_Report_FIXED.xlsx]Study Export'!H$3,"") | ... CH26: =IFERROR('[P021_LingoCGM_CGM_Report_FIXED.xlsx]Study Export'!CH$3,"")
A27: =IFERROR('[P022_LingoCGM_CGM_Report_FIXED.xlsx]Study Export'!A$3,"") | B27: =IFERROR('[P022_LingoCGM_CGM_Report_FIXED.xlsx]Study Export'!B$3,"") | C27: =IFERROR('[P022_LingoCGM_CGM_Report_FIXED.xlsx]Study Export'!C$3,"") | D27: =IFERROR('[P022_LingoCGM_CGM_Report_FIXED.xlsx]Study Export'!D$3,"") | E27: =IFERROR('[P022_LingoCGM_CGM_Report_FIXED.xlsx]Study Export'!E$3,"") | F27: =IFERROR('[P022_LingoCGM_CGM_Report_FIXED.xlsx]Study Export'!F$3,"") | G27: =IFERROR('[P022_LingoCGM_CGM_Report_FIXED.xlsx]Study Export'!G$3,"") | H27: =IFERROR('[P022_LingoCGM_CGM_Report_FIXED.xlsx]Study Export'!H$3,"") | ... CH27: =IFERROR('[P022_LingoCGM_CGM_Report_FIXED.xlsx]Study Export'!CH$3,"")
A28: =IFERROR('[P023_LingoCGM_CGM_Report_FIXED.xlsx]Study Export'!A$3,"") | B28: =IFERROR('[P023_LingoCGM_CGM_Report_FIXED.xlsx]Study Export'!B$3,"") | C28: =IFERROR('[P023_LingoCGM_CGM_Report_FIXED.xlsx]Study Export'!C$3,"") | D28: =IFERROR('[P023_LingoCGM_CGM_Report_FIXED.xlsx]Study Export'!D$3,"") | E28: =IFERROR('[P023_LingoCGM_CGM_Report_FIXED.xlsx]Study Export'!E$3,"") | F28: =IFERROR('[P023_LingoCGM_CGM_Report_FIXED.xlsx]Study Export'!F$3,"") | G28: =IFERROR('[P023_LingoCGM_CGM_Report_FIXED.xlsx]Study Export'!G$3,"") | H28: =IFERROR('[P023_LingoCGM_CGM_Report_FIXED.xlsx]Study Export'!H$3,"") | ... CH28: =IFERROR('[P023_LingoCGM_CGM_Report_FIXED.xlsx]Study Export'!CH$3,"")
A29: =IFERROR('[P024_LingoCGM_CGM_Report_FIXED.xlsx]Study Export'!A$3,"") | B29: =IFERROR('[P024_LingoCGM_CGM_Report_FIXED.xlsx]Study Export'!B$3,"") | C29: =IFERROR('[P024_LingoCGM_CGM_Report_FIXED.xlsx]Study Export'!C$3,"") | D29: =IFERROR('[P024_LingoCGM_CGM_Report_FIXED.xlsx]Study Export'!D$3,"") | E29: =IFERROR('[P024_LingoCGM_CGM_Report_FIXED.xlsx]Study Export'!E$3,"") | F29: =IFERROR('[P024_LingoCGM_CGM_Report_FIXED.xlsx]Study Export'!F$3,"") | G29: =IFERROR('[P024_LingoCGM_CGM_Report_FIXED.xlsx]Study Export'!G$3,"") | H29: =IFERROR('[P024_LingoCGM_CGM_Report_FIXED.xlsx]Study Export'!H$3,"") | ... CH29: =IFERROR('[P024_LingoCGM_CGM_Report_FIXED.xlsx]Study Export'!CH$3,"")
A30: =IFERROR('[P025_LingoCGM_CGM_Report_FIXED.xlsx]Study Export'!A$3,"") | B30: =IFERROR('[P025_LingoCGM_CGM_Report_FIXED.xlsx]Study Export'!B$3,"") | C30: =IFERROR('[P025_LingoCGM_CGM_Report_FIXED.xlsx]Study Export'!C$3,"") | D30: =IFERROR('[P025_LingoCGM_CGM_Report_FIXED.xlsx]Study Export'!D$3,"") | E30: =IFERROR('[P025_LingoCGM_CGM_Report_FIXED.xlsx]Study Export'!E$3,"") | F30: =IFERROR('[P025_LingoCGM_CGM_Report_FIXED.xlsx]Study Export'!F$3,"") | G30: =IFERROR('[P025_LingoCGM_CGM_Report_FIXED.xlsx]Study Export'!G$3,"") | H30: =IFERROR('[P025_LingoCGM_CGM_Report_FIXED.xlsx]Study Export'!H$3,"") | ... CH30: =IFERROR('[P025_LingoCGM_CGM_Report_FIXED.xlsx]Study Export'!CH$3,"")
A31: =IFERROR('[P026_LingoCGM_CGM_Report_FIXED.xlsx]Study Export'!A$3,"") | B31: =IFERROR('[P026_LingoCGM_CGM_Report_FIXED.xlsx]Study Export'!B$3,"") | C31: =IFERROR('[P026_LingoCGM_CGM_Report_FIXED.xlsx]Study Export'!C$3,"") | D31: =IFERROR('[P026_LingoCGM_CGM_Report_FIXED.xlsx]Study Export'!D$3,"") | E31: =IFERROR('[P026_LingoCGM_CGM_Report_FIXED.xlsx]Study Export'!E$3,"") | F31: =IFERROR('[P026_LingoCGM_CGM_Report_FIXED.xlsx]Study Export'!F$3,"") | G31: =IFERROR('[P026_LingoCGM_CGM_Report_FIXED.xlsx]Study Export'!G$3,"") | H31: =IFERROR('[P026_LingoCGM_CGM_Report_FIXED.xlsx]Study Export'!H$3,"") | ... CH31: =IFERROR('[P026_LingoCGM_CGM_Report_FIXED.xlsx]Study Export'!CH$3,"")
A32: =IFERROR('[P027_LingoCGM_CGM_Report_FIXED.xlsx]Study Export'!A$3,"") | B32: =IFERROR('[P027_LingoCGM_CGM_Report_FIXED.xlsx]Study Export'!B$3,"") | C32: =IFERROR('[P027_LingoCGM_CGM_Report_FIXED.xlsx]Study Export'!C$3,"") | D32: =IFERROR('[P027_LingoCGM_CGM_Report_FIXED.xlsx]Study Export'!D$3,"") | E32: =IFERROR('[P027_LingoCGM_CGM_Report_FIXED.xlsx]Study Export'!E$3,"") | F32: =IFERROR('[P027_LingoCGM_CGM_Report_FIXED.xlsx]Study Export'!F$3,"") | G32: =IFERROR('[P027_LingoCGM_CGM_Report_FIXED.xlsx]Study Export'!G$3,"") | H32: =IFERROR('[P027_LingoCGM_CGM_Report_FIXED.xlsx]Study Export'!H$3,"") | ... CH32: =IFERROR('[P027_LingoCGM_CGM_Report_FIXED.xlsx]Study Export'!CH$3,"")
A33: =IFERROR('[P028_LingoCGM_CGM_Report_FIXED.xlsx]Study Export'!A$3,"") | B33: =IFERROR('[P028_LingoCGM_CGM_Report_FIXED.xlsx]Study Export'!B$3,"") | C33: =IFERROR('[P028_LingoCGM_CGM_Report_FIXED.xlsx]Study Export'!C$3,"") | D33: =IFERROR('[P028_LingoCGM_CGM_Report_FIXED.xlsx]Study Export'!D$3,"") | E33: =IFERROR('[P028_LingoCGM_CGM_Report_FIXED.xlsx]Study Export'!E$3,"") | F33: =IFERROR('[P028_LingoCGM_CGM_Report_FIXED.xlsx]Study Export'!F$3,"") | G33: =IFERROR('[P028_LingoCGM_CGM_Report_FIXED.xlsx]Study Export'!G$3,"") | H33: =IFERROR('[P028_LingoCGM_CGM_Report_FIXED.xlsx]Study Export'!H$3,"") | ... CH33: =IFERROR('[P028_LingoCGM_CGM_Report_FIXED.xlsx]Study Export'!CH$3,"")
A34: =IFERROR('[P029_LingoCGM_CGM_Report_FIXED.xlsx]Study Export'!A$3,"") | B34: =IFERROR('[P029_LingoCGM_CGM_Report_FIXED.xlsx]Study Export'!B$3,"") | C34: =IFERROR('[P029_LingoCGM_CGM_Report_FIXED.xlsx]Study Export'!C$3,"") | D34: =IFERROR('[P029_LingoCGM_CGM_Report_FIXED.xlsx]Study Export'!D$3,"") | E34: =IFERROR('[P029_LingoCGM_CGM_Report_FIXED.xlsx]Study Export'!E$3,"") | F34: =IFERROR('[P029_LingoCGM_CGM_Report_FIXED.xlsx]Study Export'!F$3,"") | G34: =IFERROR('[P029_LingoCGM_CGM_Report_FIXED.xlsx]Study Export'!G$3,"") | H34: =IFERROR('[P029_LingoCGM_CGM_Report_FIXED.xlsx]Study Export'!H$3,"") | ... CH34: =IFERROR('[P029_LingoCGM_CGM_Report_FIXED.xlsx]Study Export'!CH$3,"")
A35: =IFERROR('[P030_LingoCGM_CGM_Report_FIXED.xlsx]Study Export'!A$3,"") | B35: =IFERROR('[P030_LingoCGM_CGM_Report_FIXED.xlsx]Study Export'!B$3,"") | C35: =IFERROR('[P030_LingoCGM_CGM_Report_FIXED.xlsx]Study Export'!C$3,"") | D35: =IFERROR('[P030_LingoCGM_CGM_Report_FIXED.xlsx]Study Export'!D$3,"") | E35: =IFERROR('[P030_LingoCGM_CGM_Report_FIXED.xlsx]Study Export'!E$3,"") | F35: =IFERROR('[P030_LingoCGM_CGM_Report_FIXED.xlsx]Study Export'!F$3,"") | G35: =IFERROR('[P030_LingoCGM_CGM_Report_FIXED.xlsx]Study Export'!G$3,"") | H35: =IFERROR('[P030_LingoCGM_CGM_Report_FIXED.xlsx]Study Export'!H$3,"") | ... CH35: =IFERROR('[P030_LingoCGM_CGM_Report_FIXED.xlsx]Study Export'!CH$3,"")

Sheet Pasted_Exports
A1: Manual Paste Area - Study Export rows
A3: Paste values from each participant workbook's Study Export row 3 into rows 6-35. This overrides File_Intake for that participant.
A5: Participant ID | B5: Treatment Arm | C5: Dose Detail | D5: Source Workbook | E5: Metformin Start Date | F5: Washout Days | G5: Total Readings | H5: Total Days | I5: Off Readings | J5: On Readings | K5: Off Days | L5: On Days | M5: Avg Glucose Off | N5: Avg Glucose On | O5: Avg Glucose Delta | P5: GMI Off | Q5: GMI On | R5: GMI Delta | S5: TIR Off | T5: TIR On | U5: TIR Delta | V5: TBR L2 Off | W5: TBR L2 On | X5: TBR L2 Delta | Y5: TBR L1 Off | Z5: TBR L1 On | AA5: TBR L1 Delta | AB5: TAR L1 Off | AC5: TAR L1 On | AD5: TAR L1 Delta | AE5: TAR L2 Off | AF5: TAR L2 On | AG5: TAR L2 Delta | AH5: Daily Hyper AUC Off | AI5: Daily Hyper AUC On | AJ5: Daily Hyper AUC Delta | AK5: Daily Hypo AUC Off | AL5: Daily Hypo AUC On | AM5: Daily Hypo AUC Delta | AN5: LBGI Off | AO5: LBGI On | AP5: LBGI Delta | AQ5: HBGI Off | AR5: HBGI On | AS5: HBGI Delta | AT5: SD Off | AU5: SD On | AV5: SD Delta | AW5: CV Off | AX5: CV On | AY5: CV Delta | AZ5: MODD Off | BA5: MODD On | BB5: MODD Delta | BC5: M Value Off | BD5: M Value On | BE5: M Value Delta | BF5: GRI Off | BG5: GRI On | BH5: GRI Delta | BI5: 12-3 AM Off | BJ5: 12-3 AM On | BK5: 12-3 AM Delta | BL5: 3-6 AM Off | BM5: 3-6 AM On | BN5: 3-6 AM Delta | BO5: 6-9 AM Off | BP5: 6-9 AM On | BQ5: 6-9 AM Delta | BR5: Median Off | BS5: Median On | BT5: Median Delta | BU5: P90 Off | BV5: P90 On | BW5: P90 Delta | BX5: Days Logged | BY5: Avg Weight Off (lb) | BZ5: Avg Weight On (lb) | CA5: Weight Change (lb) | CB5: Weight Change % | CC5: Avg Dose Time (On) | CD5: Dose Time SD (min) | CE5: Dose-Time Days (On) | CF5: Avg Taste (1-5) | CG5: Avg Aftertaste (1-5) | CH5: Taste Days Logged

Sheet Participant_Metrics
A1: Participant Metrics and Derived Efficacy Flags
A3: Rows combine pasted Study Export data first, then File_Intake links. Derived columns use editable thresholds from Study_Setup.
A5: Participant ID | B5: Treatment Arm | C5: Dose Detail | D5: Source Workbook | E5: Metformin Start Date | F5: Washout Days | G5: Total Readings | H5: Total Days | I5: Off Readings | J5: On Readings | K5: Off Days | L5: On Days | M5: Avg Glucose Off | N5: Avg Glucose On | O5: Avg Glucose Delta | P5: GMI Off | Q5: GMI On | R5: GMI Delta | S5: TIR Off | T5: TIR On | U5: TIR Delta | V5: TBR L2 Off | W5: TBR L2 On | X5: TBR L2 Delta | Y5: TBR L1 Off | Z5: TBR L1 On | AA5: TBR L1 Delta | AB5: TAR L1 Off | AC5: TAR L1 On | AD5: TAR L1 Delta | AE5: TAR L2 Off | AF5: TAR L2 On | AG5: TAR L2 Delta | AH5: Daily Hyper AUC Off | AI5: Daily Hyper AUC On | AJ5: Daily Hyper AUC Delta | AK5: Daily Hypo AUC Off | AL5: Daily Hypo AUC On | AM5: Daily Hypo AUC Delta | AN5: LBGI Off | AO5: LBGI On | AP5: LBGI Delta | AQ5: HBGI Off | AR5: HBGI On | AS5: HBGI Delta | AT5: SD Off | AU5: SD On | AV5: SD Delta | AW5: CV Off | AX5: CV On | AY5: CV Delta | AZ5: MODD Off | BA5: MODD On | BB5: MODD Delta | BC5: M Value Off | BD5: M Value On | BE5: M Value Delta | BF5: GRI Off | BG5: GRI On | BH5: GRI Delta | BI5: 12-3 AM Off | BJ5: 12-3 AM On | BK5: 12-3 AM Delta | BL5: 3-6 AM Off | BM5: 3-6 AM On | BN5: 3-6 AM Delta | BO5: 6-9 AM Off | BP5: 6-9 AM On | BQ5: 6-9 AM Delta | BR5: Median Off | BS5: Median On | BT5: Median Delta | BU5: P90 Off | BV5: P90 On | BW5: P90 Delta | BX5: Include Flag | BY5: QC Notes | BZ5: Mean Glucose Reduction | CA5: Mean Glucose Reduction % | CB5: GMI Reduction | CC5: TIR Gain | CD5: Hyper AUC Reduction | CE5: Hyper AUC Reduction % | CF5: HBGI Reduction | CG5: Fasting 6-9 AM Reduction | CH5: Overnight 12-3 AM Reduction | CI5: Dawn 3-6 AM Reduction | CJ5: GRI Reduction | CK5: M Value Reduction | CL5: No Hypo Harm Flag | CM5: Responder Flag | CN5: Composite Efficacy Score | CO5: Days Logged | CP5: Avg Weight Off (lb) | CQ5: Avg Weight On (lb) | CR5: Weight Change (lb) | CS5: Weight Change % | CT5: Avg Dose Time (On) | CU5: Dose Time SD (min) | CV5: Dose-Time Days (On) | CW5: Avg Taste (1-5) | CX5: Avg Aftertaste (1-5) | CY5: Taste Days Logged
A6: =IF('Pasted_Exports'!A6<>"",'Pasted_Exports'!A6,'File_Intake'!A6) | B6: =IF('Pasted_Exports'!B6<>"",'Pasted_Exports'!B6,'File_Intake'!B6) | C6: =IF('Pasted_Exports'!C6<>"",'Pasted_Exports'!C6,'File_Intake'!C6) | D6: =IF('Pasted_Exports'!D6<>"",'Pasted_Exports'!D6,'File_Intake'!D6) | E6: =IF('Pasted_Exports'!E6<>"",'Pasted_Exports'!E6,'File_Intake'!E6) | F6: =IF('Pasted_Exports'!F6<>"",'Pasted_Exports'!F6,'File_Intake'!F6) | G6: =IF('Pasted_Exports'!G6<>"",'Pasted_Exports'!G6,'File_Intake'!G6) | H6: =IF('Pasted_Exports'!H6<>"",'Pasted_Exports'!H6,'File_Intake'!H6) | ... BW6: =IF('Pasted_Exports'!BW6<>"",'Pasted_Exports'!BW6,'File_Intake'!BW6) | BX6: =IF(AND($A6<>"",$B6<>"",$K6>='Study_Setup'!$B$14,$L6>='Study_Setup'!$B$15),1,0) | BY6: =IF($A6="","",TEXTJOIN("; ",TRUE,IF($B6="","Missing arm",""),IF($K6<'Study_Setup'!$B$14,"Low off-days",""),IF($L6<'Study_Setup'!$B$15,"Low on-days",""),IF($AM6>'Study_Setup'!$B$19,"Hypo burden increased",""))) | BZ6: =IFERROR($M6-$N6,"") | CA6: =IFERROR(($M6-$N6)/$M6,"") | CB6: =IFERROR($P6-$Q6,"") | CC6: =IFERROR($T6-$S6,"") | CD6: =IFERROR($AH6-$AI6,"") | CE6: =IFERROR(($AH6-$AI6)/$AH6,"") | CF6: =IFERROR($AQ6-$AR6,"") | CG6: =IFERROR($BO6-$BP6,"") | CH6: =IFERROR($BI6-$BJ6,"") | CI6: =IFERROR($BL6-$BM6,"") | CJ6: =IFERROR($BF6-$BG6,"") | CK6: =IFERROR($BC6-$BD6,"") | CL6: =IF($A6="","",IF($AM6<='Study_Setup'!$B$19,1,0)) | CM6: =IF($A6="","",IF(AND($BZ6>='Study_Setup'!$B$16,$CC6>='Study_Setup'!$B$17,$CE6>='Study_Setup'!$B$18,$CL6=1),1,0)) | CN6: =IFERROR(40*MIN(1,$BZ6/'Study_Setup'!$B$16)+25*MIN(1,$CC6/'Study_Setup'!$B$17)+25*MIN(1,$CE6/'Study_Setup'!$B$18)+10*$CL6,"") | CO6: =IF('Pasted_Exports'!BX6<>"",'Pasted_Exports'!BX6,'File_Intake'!BX6) | CP6: =IF('Pasted_Exports'!BY6<>"",'Pasted_Exports'!BY6,'File_Intake'!BY6) | CQ6: =IF('Pasted_Exports'!BZ6<>"",'Pasted_Exports'!BZ6,'File_Intake'!BZ6) | CR6: =IF('Pasted_Exports'!CA6<>"",'Pasted_Exports'!CA6,'File_Intake'!CA6) | CS6: =IF('Pasted_Exports'!CB6<>"",'Pasted_Exports'!CB6,'File_Intake'!CB6) | CT6: =IF('Pasted_Exports'!CC6<>"",'Pasted_Exports'!CC6,'File_Intake'!CC6) | CU6: =IF('Pasted_Exports'!CD6<>"",'Pasted_Exports'!CD6,'File_Intake'!CD6) | CV6: =IF('Pasted_Exports'!CE6<>"",'Pasted_Exports'!CE6,'File_Intake'!CE6) | ... CY6: =IF('Pasted_Exports'!CH6<>"",'Pasted_Exports'!CH6,'File_Intake'!CH6)
A7: =IF('Pasted_Exports'!A7<>"",'Pasted_Exports'!A7,'File_Intake'!A7) | B7: =IF('Pasted_Exports'!B7<>"",'Pasted_Exports'!B7,'File_Intake'!B7) | C7: =IF('Pasted_Exports'!C7<>"",'Pasted_Exports'!C7,'File_Intake'!C7) | D7: =IF('Pasted_Exports'!D7<>"",'Pasted_Exports'!D7,'File_Intake'!D7) | E7: =IF('Pasted_Exports'!E7<>"",'Pasted_Exports'!E7,'File_Intake'!E7) | F7: =IF('Pasted_Exports'!F7<>"",'Pasted_Exports'!F7,'File_Intake'!F7) | G7: =IF('Pasted_Exports'!G7<>"",'Pasted_Exports'!G7,'File_Intake'!G7) | H7: =IF('Pasted_Exports'!H7<>"",'Pasted_Exports'!H7,'File_Intake'!H7) | ... BW7: =IF('Pasted_Exports'!BW7<>"",'Pasted_Exports'!BW7,'File_Intake'!BW7) | BX7: =IF(AND($A7<>"",$B7<>"",$K7>='Study_Setup'!$B$14,$L7>='Study_Setup'!$B$15),1,0) | BY7: =IF($A7="","",TEXTJOIN("; ",TRUE,IF($B7="","Missing arm",""),IF($K7<'Study_Setup'!$B$14,"Low off-days",""),IF($L7<'Study_Setup'!$B$15,"Low on-days",""),IF($AM7>'Study_Setup'!$B$19,"Hypo burden increased",""))) | BZ7: =IFERROR($M7-$N7,"") | CA7: =IFERROR(($M7-$N7)/$M7,"") | CB7: =IFERROR($P7-$Q7,"") | CC7: =IFERROR($T7-$S7,"") | CD7: =IFERROR($AH7-$AI7,"") | CE7: =IFERROR(($AH7-$AI7)/$AH7,"") | CF7: =IFERROR($AQ7-$AR7,"") | CG7: =IFERROR($BO7-$BP7,"") | CH7: =IFERROR($BI7-$BJ7,"") | CI7: =IFERROR($BL7-$BM7,"") | CJ7: =IFERROR($BF7-$BG7,"") | CK7: =IFERROR($BC7-$BD7,"") | CL7: =IF($A7="","",IF($AM7<='Study_Setup'!$B$19,1,0)) | CM7: =IF($A7="","",IF(AND($BZ7>='Study_Setup'!$B$16,$CC7>='Study_Setup'!$B$17,$CE7>='Study_Setup'!$B$18,$CL7=1),1,0)) | CN7: =IFERROR(40*MIN(1,$BZ7/'Study_Setup'!$B$16)+25*MIN(1,$CC7/'Study_Setup'!$B$17)+25*MIN(1,$CE7/'Study_Setup'!$B$18)+10*$CL7,"") | CO7: =IF('Pasted_Exports'!BX7<>"",'Pasted_Exports'!BX7,'File_Intake'!BX7) | CP7: =IF('Pasted_Exports'!BY7<>"",'Pasted_Exports'!BY7,'File_Intake'!BY7) | CQ7: =IF('Pasted_Exports'!BZ7<>"",'Pasted_Exports'!BZ7,'File_Intake'!BZ7) | CR7: =IF('Pasted_Exports'!CA7<>"",'Pasted_Exports'!CA7,'File_Intake'!CA7) | CS7: =IF('Pasted_Exports'!CB7<>"",'Pasted_Exports'!CB7,'File_Intake'!CB7) | CT7: =IF('Pasted_Exports'!CC7<>"",'Pasted_Exports'!CC7,'File_Intake'!CC7) | CU7: =IF('Pasted_Exports'!CD7<>"",'Pasted_Exports'!CD7,'File_Intake'!CD7) | CV7: =IF('Pasted_Exports'!CE7<>"",'Pasted_Exports'!CE7,'File_Intake'!CE7) | ... CY7: =IF('Pasted_Exports'!CH7<>"",'Pasted_Exports'!CH7,'File_Intake'!CH7)
A8: =IF('Pasted_Exports'!A8<>"",'Pasted_Exports'!A8,'File_Intake'!A8) | B8: =IF('Pasted_Exports'!B8<>"",'Pasted_Exports'!B8,'File_Intake'!B8) | C8: =IF('Pasted_Exports'!C8<>"",'Pasted_Exports'!C8,'File_Intake'!C8) | D8: =IF('Pasted_Exports'!D8<>"",'Pasted_Exports'!D8,'File_Intake'!D8) | E8: =IF('Pasted_Exports'!E8<>"",'Pasted_Exports'!E8,'File_Intake'!E8) | F8: =IF('Pasted_Exports'!F8<>"",'Pasted_Exports'!F8,'File_Intake'!F8) | G8: =IF('Pasted_Exports'!G8<>"",'Pasted_Exports'!G8,'File_Intake'!G8) | H8: =IF('Pasted_Exports'!H8<>"",'Pasted_Exports'!H8,'File_Intake'!H8) | ... BW8: =IF('Pasted_Exports'!BW8<>"",'Pasted_Exports'!BW8,'File_Intake'!BW8) | BX8: =IF(AND($A8<>"",$B8<>"",$K8>='Study_Setup'!$B$14,$L8>='Study_Setup'!$B$15),1,0) | BY8: =IF($A8="","",TEXTJOIN("; ",TRUE,IF($B8="","Missing arm",""),IF($K8<'Study_Setup'!$B$14,"Low off-days",""),IF($L8<'Study_Setup'!$B$15,"Low on-days",""),IF($AM8>'Study_Setup'!$B$19,"Hypo burden increased",""))) | BZ8: =IFERROR($M8-$N8,"") | CA8: =IFERROR(($M8-$N8)/$M8,"") | CB8: =IFERROR($P8-$Q8,"") | CC8: =IFERROR($T8-$S8,"") | CD8: =IFERROR($AH8-$AI8,"") | CE8: =IFERROR(($AH8-$AI8)/$AH8,"") | CF8: =IFERROR($AQ8-$AR8,"") | CG8: =IFERROR($BO8-$BP8,"") | CH8: =IFERROR($BI8-$BJ8,"") | CI8: =IFERROR($BL8-$BM8,"") | CJ8: =IFERROR($BF8-$BG8,"") | CK8: =IFERROR($BC8-$BD8,"") | CL8: =IF($A8="","",IF($AM8<='Study_Setup'!$B$19,1,0)) | CM8: =IF($A8="","",IF(AND($BZ8>='Study_Setup'!$B$16,$CC8>='Study_Setup'!$B$17,$CE8>='Study_Setup'!$B$18,$CL8=1),1,0)) | CN8: =IFERROR(40*MIN(1,$BZ8/'Study_Setup'!$B$16)+25*MIN(1,$CC8/'Study_Setup'!$B$17)+25*MIN(1,$CE8/'Study_Setup'!$B$18)+10*$CL8,"") | CO8: =IF('Pasted_Exports'!BX8<>"",'Pasted_Exports'!BX8,'File_Intake'!BX8) | CP8: =IF('Pasted_Exports'!BY8<>"",'Pasted_Exports'!BY8,'File_Intake'!BY8) | CQ8: =IF('Pasted_Exports'!BZ8<>"",'Pasted_Exports'!BZ8,'File_Intake'!BZ8) | CR8: =IF('Pasted_Exports'!CA8<>"",'Pasted_Exports'!CA8,'File_Intake'!CA8) | CS8: =IF('Pasted_Exports'!CB8<>"",'Pasted_Exports'!CB8,'File_Intake'!CB8) | CT8: =IF('Pasted_Exports'!CC8<>"",'Pasted_Exports'!CC8,'File_Intake'!CC8) | CU8: =IF('Pasted_Exports'!CD8<>"",'Pasted_Exports'!CD8,'File_Intake'!CD8) | CV8: =IF('Pasted_Exports'!CE8<>"",'Pasted_Exports'!CE8,'File_Intake'!CE8) | ... CY8: =IF('Pasted_Exports'!CH8<>"",'Pasted_Exports'!CH8,'File_Intake'!CH8)
A9: =IF('Pasted_Exports'!A9<>"",'Pasted_Exports'!A9,'File_Intake'!A9) | B9: =IF('Pasted_Exports'!B9<>"",'Pasted_Exports'!B9,'File_Intake'!B9) | C9: =IF('Pasted_Exports'!C9<>"",'Pasted_Exports'!C9,'File_Intake'!C9) | D9: =IF('Pasted_Exports'!D9<>"",'Pasted_Exports'!D9,'File_Intake'!D9) | E9: =IF('Pasted_Exports'!E9<>"",'Pasted_Exports'!E9,'File_Intake'!E9) | F9: =IF('Pasted_Exports'!F9<>"",'Pasted_Exports'!F9,'File_Intake'!F9) | G9: =IF('Pasted_Exports'!G9<>"",'Pasted_Exports'!G9,'File_Intake'!G9) | H9: =IF('Pasted_Exports'!H9<>"",'Pasted_Exports'!H9,'File_Intake'!H9) | ... BW9: =IF('Pasted_Exports'!BW9<>"",'Pasted_Exports'!BW9,'File_Intake'!BW9) | BX9: =IF(AND($A9<>"",$B9<>"",$K9>='Study_Setup'!$B$14,$L9>='Study_Setup'!$B$15),1,0) | BY9: =IF($A9="","",TEXTJOIN("; ",TRUE,IF($B9="","Missing arm",""),IF($K9<'Study_Setup'!$B$14,"Low off-days",""),IF($L9<'Study_Setup'!$B$15,"Low on-days",""),IF($AM9>'Study_Setup'!$B$19,"Hypo burden increased",""))) | BZ9: =IFERROR($M9-$N9,"") | CA9: =IFERROR(($M9-$N9)/$M9,"") | CB9: =IFERROR($P9-$Q9,"") | CC9: =IFERROR($T9-$S9,"") | CD9: =IFERROR($AH9-$AI9,"") | CE9: =IFERROR(($AH9-$AI9)/$AH9,"") | CF9: =IFERROR($AQ9-$AR9,"") | CG9: =IFERROR($BO9-$BP9,"") | CH9: =IFERROR($BI9-$BJ9,"") | CI9: =IFERROR($BL9-$BM9,"") | CJ9: =IFERROR($BF9-$BG9,"") | CK9: =IFERROR($BC9-$BD9,"") | CL9: =IF($A9="","",IF($AM9<='Study_Setup'!$B$19,1,0)) | CM9: =IF($A9="","",IF(AND($BZ9>='Study_Setup'!$B$16,$CC9>='Study_Setup'!$B$17,$CE9>='Study_Setup'!$B$18,$CL9=1),1,0)) | CN9: =IFERROR(40*MIN(1,$BZ9/'Study_Setup'!$B$16)+25*MIN(1,$CC9/'Study_Setup'!$B$17)+25*MIN(1,$CE9/'Study_Setup'!$B$18)+10*$CL9,"") | CO9: =IF('Pasted_Exports'!BX9<>"",'Pasted_Exports'!BX9,'File_Intake'!BX9) | CP9: =IF('Pasted_Exports'!BY9<>"",'Pasted_Exports'!BY9,'File_Intake'!BY9) | CQ9: =IF('Pasted_Exports'!BZ9<>"",'Pasted_Exports'!BZ9,'File_Intake'!BZ9) | CR9: =IF('Pasted_Exports'!CA9<>"",'Pasted_Exports'!CA9,'File_Intake'!CA9) | CS9: =IF('Pasted_Exports'!CB9<>"",'Pasted_Exports'!CB9,'File_Intake'!CB9) | CT9: =IF('Pasted_Exports'!CC9<>"",'Pasted_Exports'!CC9,'File_Intake'!CC9) | CU9: =IF('Pasted_Exports'!CD9<>"",'Pasted_Exports'!CD9,'File_Intake'!CD9) | CV9: =IF('Pasted_Exports'!CE9<>"",'Pasted_Exports'!CE9,'File_Intake'!CE9) | ... CY9: =IF('Pasted_Exports'!CH9<>"",'Pasted_Exports'!CH9,'File_Intake'!CH9)
A10: =IF('Pasted_Exports'!A10<>"",'Pasted_Exports'!A10,'File_Intake'!A10) | B10: =IF('Pasted_Exports'!B10<>"",'Pasted_Exports'!B10,'File_Intake'!B10) | C10: =IF('Pasted_Exports'!C10<>"",'Pasted_Exports'!C10,'File_Intake'!C10) | D10: =IF('Pasted_Exports'!D10<>"",'Pasted_Exports'!D10,'File_Intake'!D10) | E10: =IF('Pasted_Exports'!E10<>"",'Pasted_Exports'!E10,'File_Intake'!E10) | F10: =IF('Pasted_Exports'!F10<>"",'Pasted_Exports'!F10,'File_Intake'!F10) | G10: =IF('Pasted_Exports'!G10<>"",'Pasted_Exports'!G10,'File_Intake'!G10) | H10: =IF('Pasted_Exports'!H10<>"",'Pasted_Exports'!H10,'File_Intake'!H10) | ... BW10: =IF('Pasted_Exports'!BW10<>"",'Pasted_Exports'!BW10,'File_Intake'!BW10) | BX10: =IF(AND($A10<>"",$B10<>"",$K10>='Study_Setup'!$B$14,$L10>='Study_Setup'!$B$15),1,0) | BY10: =IF($A10="","",TEXTJOIN("; ",TRUE,IF($B10="","Missing arm",""),IF($K10<'Study_Setup'!$B$14,"Low off-days",""),IF($L10<'Study_Setup'!$B$15,"Low on-days",""),IF($AM10>'Study_Setup'!$B$19,"Hypo burden increased",""))) | BZ10: =IFERROR($M10-$N10,"") | CA10: =IFERROR(($M10-$N10)/$M10,"") | CB10: =IFERROR($P10-$Q10,"") | CC10: =IFERROR($T10-$S10,"") | CD10: =IFERROR($AH10-$AI10,"") | CE10: =IFERROR(($AH10-$AI10)/$AH10,"") | CF10: =IFERROR($AQ10-$AR10,"") | CG10: =IFERROR($BO10-$BP10,"") | CH10: =IFERROR($BI10-$BJ10,"") | CI10: =IFERROR($BL10-$BM10,"") | CJ10: =IFERROR($BF10-$BG10,"") | CK10: =IFERROR($BC10-$BD10,"") | CL10: =IF($A10="","",IF($AM10<='Study_Setup'!$B$19,1,0)) | CM10: =IF($A10="","",IF(AND($BZ10>='Study_Setup'!$B$16,$CC10>='Study_Setup'!$B$17,$CE10>='Study_Setup'!$B$18,$CL10=1),1,0)) | CN10: =IFERROR(40*MIN(1,$BZ10/'Study_Setup'!$B$16)+25*MIN(1,$CC10/'Study_Setup'!$B$17)+25*MIN(1,$CE10/'Study_Setup'!$B$18)+10*$CL10,"") | CO10: =IF('Pasted_Exports'!BX10<>"",'Pasted_Exports'!BX10,'File_Intake'!BX10) | CP10: =IF('Pasted_Exports'!BY10<>"",'Pasted_Exports'!BY10,'File_Intake'!BY10) | CQ10: =IF('Pasted_Exports'!BZ10<>"",'Pasted_Exports'!BZ10,'File_Intake'!BZ10) | CR10: =IF('Pasted_Exports'!CA10<>"",'Pasted_Exports'!CA10,'File_Intake'!CA10) | CS10: =IF('Pasted_Exports'!CB10<>"",'Pasted_Exports'!CB10,'File_Intake'!CB10) | CT10: =IF('Pasted_Exports'!CC10<>"",'Pasted_Exports'!CC10,'File_Intake'!CC10) | CU10: =IF('Pasted_Exports'!CD10<>"",'Pasted_Exports'!CD10,'File_Intake'!CD10) | CV10: =IF('Pasted_Exports'!CE10<>"",'Pasted_Exports'!CE10,'File_Intake'!CE10) | ... CY10: =IF('Pasted_Exports'!CH10<>"",'Pasted_Exports'!CH10,'File_Intake'!CH10)
A11: =IF('Pasted_Exports'!A11<>"",'Pasted_Exports'!A11,'File_Intake'!A11) | B11: =IF('Pasted_Exports'!B11<>"",'Pasted_Exports'!B11,'File_Intake'!B11) | C11: =IF('Pasted_Exports'!C11<>"",'Pasted_Exports'!C11,'File_Intake'!C11) | D11: =IF('Pasted_Exports'!D11<>"",'Pasted_Exports'!D11,'File_Intake'!D11) | E11: =IF('Pasted_Exports'!E11<>"",'Pasted_Exports'!E11,'File_Intake'!E11) | F11: =IF('Pasted_Exports'!F11<>"",'Pasted_Exports'!F11,'File_Intake'!F11) | G11: =IF('Pasted_Exports'!G11<>"",'Pasted_Exports'!G11,'File_Intake'!G11) | H11: =IF('Pasted_Exports'!H11<>"",'Pasted_Exports'!H11,'File_Intake'!H11) | ... BW11: =IF('Pasted_Exports'!BW11<>"",'Pasted_Exports'!BW11,'File_Intake'!BW11) | BX11: =IF(AND($A11<>"",$B11<>"",$K11>='Study_Setup'!$B$14,$L11>='Study_Setup'!$B$15),1,0) | BY11: =IF($A11="","",TEXTJOIN("; ",TRUE,IF($B11="","Missing arm",""),IF($K11<'Study_Setup'!$B$14,"Low off-days",""),IF($L11<'Study_Setup'!$B$15,"Low on-days",""),IF($AM11>'Study_Setup'!$B$19,"Hypo burden increased",""))) | BZ11: =IFERROR($M11-$N11,"") | CA11: =IFERROR(($M11-$N11)/$M11,"") | CB11: =IFERROR($P11-$Q11,"") | CC11: =IFERROR($T11-$S11,"") | CD11: =IFERROR($AH11-$AI11,"") | CE11: =IFERROR(($AH11-$AI11)/$AH11,"") | CF11: =IFERROR($AQ11-$AR11,"") | CG11: =IFERROR($BO11-$BP11,"") | CH11: =IFERROR($BI11-$BJ11,"") | CI11: =IFERROR($BL11-$BM11,"") | CJ11: =IFERROR($BF11-$BG11,"") | CK11: =IFERROR($BC11-$BD11,"") | CL11: =IF($A11="","",IF($AM11<='Study_Setup'!$B$19,1,0)) | CM11: =IF($A11="","",IF(AND($BZ11>='Study_Setup'!$B$16,$CC11>='Study_Setup'!$B$17,$CE11>='Study_Setup'!$B$18,$CL11=1),1,0)) | CN11: =IFERROR(40*MIN(1,$BZ11/'Study_Setup'!$B$16)+25*MIN(1,$CC11/'Study_Setup'!$B$17)+25*MIN(1,$CE11/'Study_Setup'!$B$18)+10*$CL11,"") | CO11: =IF('Pasted_Exports'!BX11<>"",'Pasted_Exports'!BX11,'File_Intake'!BX11) | CP11: =IF('Pasted_Exports'!BY11<>"",'Pasted_Exports'!BY11,'File_Intake'!BY11) | CQ11: =IF('Pasted_Exports'!BZ11<>"",'Pasted_Exports'!BZ11,'File_Intake'!BZ11) | CR11: =IF('Pasted_Exports'!CA11<>"",'Pasted_Exports'!CA11,'File_Intake'!CA11) | CS11: =IF('Pasted_Exports'!CB11<>"",'Pasted_Exports'!CB11,'File_Intake'!CB11) | CT11: =IF('Pasted_Exports'!CC11<>"",'Pasted_Exports'!CC11,'File_Intake'!CC11) | CU11: =IF('Pasted_Exports'!CD11<>"",'Pasted_Exports'!CD11,'File_Intake'!CD11) | CV11: =IF('Pasted_Exports'!CE11<>"",'Pasted_Exports'!CE11,'File_Intake'!CE11) | ... CY11: =IF('Pasted_Exports'!CH11<>"",'Pasted_Exports'!CH11,'File_Intake'!CH11)
A12: =IF('Pasted_Exports'!A12<>"",'Pasted_Exports'!A12,'File_Intake'!A12) | B12: =IF('Pasted_Exports'!B12<>"",'Pasted_Exports'!B12,'File_Intake'!B12) | C12: =IF('Pasted_Exports'!C12<>"",'Pasted_Exports'!C12,'File_Intake'!C12) | D12: =IF('Pasted_Exports'!D12<>"",'Pasted_Exports'!D12,'File_Intake'!D12) | E12: =IF('Pasted_Exports'!E12<>"",'Pasted_Exports'!E12,'File_Intake'!E12) | F12: =IF('Pasted_Exports'!F12<>"",'Pasted_Exports'!F12,'File_Intake'!F12) | G12: =IF('Pasted_Exports'!G12<>"",'Pasted_Exports'!G12,'File_Intake'!G12) | H12: =IF('Pasted_Exports'!H12<>"",'Pasted_Exports'!H12,'File_Intake'!H12) | ... BW12: =IF('Pasted_Exports'!BW12<>"",'Pasted_Exports'!BW12,'File_Intake'!BW12) | BX12: =IF(AND($A12<>"",$B12<>"",$K12>='Study_Setup'!$B$14,$L12>='Study_Setup'!$B$15),1,0) | BY12: =IF($A12="","",TEXTJOIN("; ",TRUE,IF($B12="","Missing arm",""),IF($K12<'Study_Setup'!$B$14,"Low off-days",""),IF($L12<'Study_Setup'!$B$15,"Low on-days",""),IF($AM12>'Study_Setup'!$B$19,"Hypo burden increased",""))) | BZ12: =IFERROR($M12-$N12,"") | CA12: =IFERROR(($M12-$N12)/$M12,"") | CB12: =IFERROR($P12-$Q12,"") | CC12: =IFERROR($T12-$S12,"") | CD12: =IFERROR($AH12-$AI12,"") | CE12: =IFERROR(($AH12-$AI12)/$AH12,"") | CF12: =IFERROR($AQ12-$AR12,"") | CG12: =IFERROR($BO12-$BP12,"") | CH12: =IFERROR($BI12-$BJ12,"") | CI12: =IFERROR($BL12-$BM12,"") | CJ12: =IFERROR($BF12-$BG12,"") | CK12: =IFERROR($BC12-$BD12,"") | CL12: =IF($A12="","",IF($AM12<='Study_Setup'!$B$19,1,0)) | CM12: =IF($A12="","",IF(AND($BZ12>='Study_Setup'!$B$16,$CC12>='Study_Setup'!$B$17,$CE12>='Study_Setup'!$B$18,$CL12=1),1,0)) | CN12: =IFERROR(40*MIN(1,$BZ12/'Study_Setup'!$B$16)+25*MIN(1,$CC12/'Study_Setup'!$B$17)+25*MIN(1,$CE12/'Study_Setup'!$B$18)+10*$CL12,"") | CO12: =IF('Pasted_Exports'!BX12<>"",'Pasted_Exports'!BX12,'File_Intake'!BX12) | CP12: =IF('Pasted_Exports'!BY12<>"",'Pasted_Exports'!BY12,'File_Intake'!BY12) | CQ12: =IF('Pasted_Exports'!BZ12<>"",'Pasted_Exports'!BZ12,'File_Intake'!BZ12) | CR12: =IF('Pasted_Exports'!CA12<>"",'Pasted_Exports'!CA12,'File_Intake'!CA12) | CS12: =IF('Pasted_Exports'!CB12<>"",'Pasted_Exports'!CB12,'File_Intake'!CB12) | CT12: =IF('Pasted_Exports'!CC12<>"",'Pasted_Exports'!CC12,'File_Intake'!CC12) | CU12: =IF('Pasted_Exports'!CD12<>"",'Pasted_Exports'!CD12,'File_Intake'!CD12) | CV12: =IF('Pasted_Exports'!CE12<>"",'Pasted_Exports'!CE12,'File_Intake'!CE12) | ... CY12: =IF('Pasted_Exports'!CH12<>"",'Pasted_Exports'!CH12,'File_Intake'!CH12)
A13: =IF('Pasted_Exports'!A13<>"",'Pasted_Exports'!A13,'File_Intake'!A13) | B13: =IF('Pasted_Exports'!B13<>"",'Pasted_Exports'!B13,'File_Intake'!B13) | C13: =IF('Pasted_Exports'!C13<>"",'Pasted_Exports'!C13,'File_Intake'!C13) | D13: =IF('Pasted_Exports'!D13<>"",'Pasted_Exports'!D13,'File_Intake'!D13) | E13: =IF('Pasted_Exports'!E13<>"",'Pasted_Exports'!E13,'File_Intake'!E13) | F13: =IF('Pasted_Exports'!F13<>"",'Pasted_Exports'!F13,'File_Intake'!F13) | G13: =IF('Pasted_Exports'!G13<>"",'Pasted_Exports'!G13,'File_Intake'!G13) | H13: =IF('Pasted_Exports'!H13<>"",'Pasted_Exports'!H13,'File_Intake'!H13) | ... BW13: =IF('Pasted_Exports'!BW13<>"",'Pasted_Exports'!BW13,'File_Intake'!BW13) | BX13: =IF(AND($A13<>"",$B13<>"",$K13>='Study_Setup'!$B$14,$L13>='Study_Setup'!$B$15),1,0) | BY13: =IF($A13="","",TEXTJOIN("; ",TRUE,IF($B13="","Missing arm",""),IF($K13<'Study_Setup'!$B$14,"Low off-days",""),IF($L13<'Study_Setup'!$B$15,"Low on-days",""),IF($AM13>'Study_Setup'!$B$19,"Hypo burden increased",""))) | BZ13: =IFERROR($M13-$N13,"") | CA13: =IFERROR(($M13-$N13)/$M13,"") | CB13: =IFERROR($P13-$Q13,"") | CC13: =IFERROR($T13-$S13,"") | CD13: =IFERROR($AH13-$AI13,"") | CE13: =IFERROR(($AH13-$AI13)/$AH13,"") | CF13: =IFERROR($AQ13-$AR13,"") | CG13: =IFERROR($BO13-$BP13,"") | CH13: =IFERROR($BI13-$BJ13,"") | CI13: =IFERROR($BL13-$BM13,"") | CJ13: =IFERROR($BF13-$BG13,"") | CK13: =IFERROR($BC13-$BD13,"") | CL13: =IF($A13="","",IF($AM13<='Study_Setup'!$B$19,1,0)) | CM13: =IF($A13="","",IF(AND($BZ13>='Study_Setup'!$B$16,$CC13>='Study_Setup'!$B$17,$CE13>='Study_Setup'!$B$18,$CL13=1),1,0)) | CN13: =IFERROR(40*MIN(1,$BZ13/'Study_Setup'!$B$16)+25*MIN(1,$CC13/'Study_Setup'!$B$17)+25*MIN(1,$CE13/'Study_Setup'!$B$18)+10*$CL13,"") | CO13: =IF('Pasted_Exports'!BX13<>"",'Pasted_Exports'!BX13,'File_Intake'!BX13) | CP13: =IF('Pasted_Exports'!BY13<>"",'Pasted_Exports'!BY13,'File_Intake'!BY13) | CQ13: =IF('Pasted_Exports'!BZ13<>"",'Pasted_Exports'!BZ13,'File_Intake'!BZ13) | CR13: =IF('Pasted_Exports'!CA13<>"",'Pasted_Exports'!CA13,'File_Intake'!CA13) | CS13: =IF('Pasted_Exports'!CB13<>"",'Pasted_Exports'!CB13,'File_Intake'!CB13) | CT13: =IF('Pasted_Exports'!CC13<>"",'Pasted_Exports'!CC13,'File_Intake'!CC13) | CU13: =IF('Pasted_Exports'!CD13<>"",'Pasted_Exports'!CD13,'File_Intake'!CD13) | CV13: =IF('Pasted_Exports'!CE13<>"",'Pasted_Exports'!CE13,'File_Intake'!CE13) | ... CY13: =IF('Pasted_Exports'!CH13<>"",'Pasted_Exports'!CH13,'File_Intake'!CH13)
A14: =IF('Pasted_Exports'!A14<>"",'Pasted_Exports'!A14,'File_Intake'!A14) | B14: =IF('Pasted_Exports'!B14<>"",'Pasted_Exports'!B14,'File_Intake'!B14) | C14: =IF('Pasted_Exports'!C14<>"",'Pasted_Exports'!C14,'File_Intake'!C14) | D14: =IF('Pasted_Exports'!D14<>"",'Pasted_Exports'!D14,'File_Intake'!D14) | E14: =IF('Pasted_Exports'!E14<>"",'Pasted_Exports'!E14,'File_Intake'!E14) | F14: =IF('Pasted_Exports'!F14<>"",'Pasted_Exports'!F14,'File_Intake'!F14) | G14: =IF('Pasted_Exports'!G14<>"",'Pasted_Exports'!G14,'File_Intake'!G14) | H14: =IF('Pasted_Exports'!H14<>"",'Pasted_Exports'!H14,'File_Intake'!H14) | ... BW14: =IF('Pasted_Exports'!BW14<>"",'Pasted_Exports'!BW14,'File_Intake'!BW14) | BX14: =IF(AND($A14<>"",$B14<>"",$K14>='Study_Setup'!$B$14,$L14>='Study_Setup'!$B$15),1,0) | BY14: =IF($A14="","",TEXTJOIN("; ",TRUE,IF($B14="","Missing arm",""),IF($K14<'Study_Setup'!$B$14,"Low off-days",""),IF($L14<'Study_Setup'!$B$15,"Low on-days",""),IF($AM14>'Study_Setup'!$B$19,"Hypo burden increased",""))) | BZ14: =IFERROR($M14-$N14,"") | CA14: =IFERROR(($M14-$N14)/$M14,"") | CB14: =IFERROR($P14-$Q14,"") | CC14: =IFERROR($T14-$S14,"") | CD14: =IFERROR($AH14-$AI14,"") | CE14: =IFERROR(($AH14-$AI14)/$AH14,"") | CF14: =IFERROR($AQ14-$AR14,"") | CG14: =IFERROR($BO14-$BP14,"") | CH14: =IFERROR($BI14-$BJ14,"") | CI14: =IFERROR($BL14-$BM14,"") | CJ14: =IFERROR($BF14-$BG14,"") | CK14: =IFERROR($BC14-$BD14,"") | CL14: =IF($A14="","",IF($AM14<='Study_Setup'!$B$19,1,0)) | CM14: =IF($A14="","",IF(AND($BZ14>='Study_Setup'!$B$16,$CC14>='Study_Setup'!$B$17,$CE14>='Study_Setup'!$B$18,$CL14=1),1,0)) | CN14: =IFERROR(40*MIN(1,$BZ14/'Study_Setup'!$B$16)+25*MIN(1,$CC14/'Study_Setup'!$B$17)+25*MIN(1,$CE14/'Study_Setup'!$B$18)+10*$CL14,"") | CO14: =IF('Pasted_Exports'!BX14<>"",'Pasted_Exports'!BX14,'File_Intake'!BX14) | CP14: =IF('Pasted_Exports'!BY14<>"",'Pasted_Exports'!BY14,'File_Intake'!BY14) | CQ14: =IF('Pasted_Exports'!BZ14<>"",'Pasted_Exports'!BZ14,'File_Intake'!BZ14) | CR14: =IF('Pasted_Exports'!CA14<>"",'Pasted_Exports'!CA14,'File_Intake'!CA14) | CS14: =IF('Pasted_Exports'!CB14<>"",'Pasted_Exports'!CB14,'File_Intake'!CB14) | CT14: =IF('Pasted_Exports'!CC14<>"",'Pasted_Exports'!CC14,'File_Intake'!CC14) | CU14: =IF('Pasted_Exports'!CD14<>"",'Pasted_Exports'!CD14,'File_Intake'!CD14) | CV14: =IF('Pasted_Exports'!CE14<>"",'Pasted_Exports'!CE14,'File_Intake'!CE14) | ... CY14: =IF('Pasted_Exports'!CH14<>"",'Pasted_Exports'!CH14,'File_Intake'!CH14)
A15: =IF('Pasted_Exports'!A15<>"",'Pasted_Exports'!A15,'File_Intake'!A15) | B15: =IF('Pasted_Exports'!B15<>"",'Pasted_Exports'!B15,'File_Intake'!B15) | C15: =IF('Pasted_Exports'!C15<>"",'Pasted_Exports'!C15,'File_Intake'!C15) | D15: =IF('Pasted_Exports'!D15<>"",'Pasted_Exports'!D15,'File_Intake'!D15) | E15: =IF('Pasted_Exports'!E15<>"",'Pasted_Exports'!E15,'File_Intake'!E15) | F15: =IF('Pasted_Exports'!F15<>"",'Pasted_Exports'!F15,'File_Intake'!F15) | G15: =IF('Pasted_Exports'!G15<>"",'Pasted_Exports'!G15,'File_Intake'!G15) | H15: =IF('Pasted_Exports'!H15<>"",'Pasted_Exports'!H15,'File_Intake'!H15) | ... BW15: =IF('Pasted_Exports'!BW15<>"",'Pasted_Exports'!BW15,'File_Intake'!BW15) | BX15: =IF(AND($A15<>"",$B15<>"",$K15>='Study_Setup'!$B$14,$L15>='Study_Setup'!$B$15),1,0) | BY15: =IF($A15="","",TEXTJOIN("; ",TRUE,IF($B15="","Missing arm",""),IF($K15<'Study_Setup'!$B$14,"Low off-days",""),IF($L15<'Study_Setup'!$B$15,"Low on-days",""),IF($AM15>'Study_Setup'!$B$19,"Hypo burden increased",""))) | BZ15: =IFERROR($M15-$N15,"") | CA15: =IFERROR(($M15-$N15)/$M15,"") | CB15: =IFERROR($P15-$Q15,"") | CC15: =IFERROR($T15-$S15,"") | CD15: =IFERROR($AH15-$AI15,"") | CE15: =IFERROR(($AH15-$AI15)/$AH15,"") | CF15: =IFERROR($AQ15-$AR15,"") | CG15: =IFERROR($BO15-$BP15,"") | CH15: =IFERROR($BI15-$BJ15,"") | CI15: =IFERROR($BL15-$BM15,"") | CJ15: =IFERROR($BF15-$BG15,"") | CK15: =IFERROR($BC15-$BD15,"") | CL15: =IF($A15="","",IF($AM15<='Study_Setup'!$B$19,1,0)) | CM15: =IF($A15="","",IF(AND($BZ15>='Study_Setup'!$B$16,$CC15>='Study_Setup'!$B$17,$CE15>='Study_Setup'!$B$18,$CL15=1),1,0)) | CN15: =IFERROR(40*MIN(1,$BZ15/'Study_Setup'!$B$16)+25*MIN(1,$CC15/'Study_Setup'!$B$17)+25*MIN(1,$CE15/'Study_Setup'!$B$18)+10*$CL15,"") | CO15: =IF('Pasted_Exports'!BX15<>"",'Pasted_Exports'!BX15,'File_Intake'!BX15) | CP15: =IF('Pasted_Exports'!BY15<>"",'Pasted_Exports'!BY15,'File_Intake'!BY15) | CQ15: =IF('Pasted_Exports'!BZ15<>"",'Pasted_Exports'!BZ15,'File_Intake'!BZ15) | CR15: =IF('Pasted_Exports'!CA15<>"",'Pasted_Exports'!CA15,'File_Intake'!CA15) | CS15: =IF('Pasted_Exports'!CB15<>"",'Pasted_Exports'!CB15,'File_Intake'!CB15) | CT15: =IF('Pasted_Exports'!CC15<>"",'Pasted_Exports'!CC15,'File_Intake'!CC15) | CU15: =IF('Pasted_Exports'!CD15<>"",'Pasted_Exports'!CD15,'File_Intake'!CD15) | CV15: =IF('Pasted_Exports'!CE15<>"",'Pasted_Exports'!CE15,'File_Intake'!CE15) | ... CY15: =IF('Pasted_Exports'!CH15<>"",'Pasted_Exports'!CH15,'File_Intake'!CH15)
A16: =IF('Pasted_Exports'!A16<>"",'Pasted_Exports'!A16,'File_Intake'!A16) | B16: =IF('Pasted_Exports'!B16<>"",'Pasted_Exports'!B16,'File_Intake'!B16) | C16: =IF('Pasted_Exports'!C16<>"",'Pasted_Exports'!C16,'File_Intake'!C16) | D16: =IF('Pasted_Exports'!D16<>"",'Pasted_Exports'!D16,'File_Intake'!D16) | E16: =IF('Pasted_Exports'!E16<>"",'Pasted_Exports'!E16,'File_Intake'!E16) | F16: =IF('Pasted_Exports'!F16<>"",'Pasted_Exports'!F16,'File_Intake'!F16) | G16: =IF('Pasted_Exports'!G16<>"",'Pasted_Exports'!G16,'File_Intake'!G16) | H16: =IF('Pasted_Exports'!H16<>"",'Pasted_Exports'!H16,'File_Intake'!H16) | ... BW16: =IF('Pasted_Exports'!BW16<>"",'Pasted_Exports'!BW16,'File_Intake'!BW16) | BX16: =IF(AND($A16<>"",$B16<>"",$K16>='Study_Setup'!$B$14,$L16>='Study_Setup'!$B$15),1,0) | BY16: =IF($A16="","",TEXTJOIN("; ",TRUE,IF($B16="","Missing arm",""),IF($K16<'Study_Setup'!$B$14,"Low off-days",""),IF($L16<'Study_Setup'!$B$15,"Low on-days",""),IF($AM16>'Study_Setup'!$B$19,"Hypo burden increased",""))) | BZ16: =IFERROR($M16-$N16,"") | CA16: =IFERROR(($M16-$N16)/$M16,"") | CB16: =IFERROR($P16-$Q16,"") | CC16: =IFERROR($T16-$S16,"") | CD16: =IFERROR($AH16-$AI16,"") | CE16: =IFERROR(($AH16-$AI16)/$AH16,"") | CF16: =IFERROR($AQ16-$AR16,"") | CG16: =IFERROR($BO16-$BP16,"") | CH16: =IFERROR($BI16-$BJ16,"") | CI16: =IFERROR($BL16-$BM16,"") | CJ16: =IFERROR($BF16-$BG16,"") | CK16: =IFERROR($BC16-$BD16,"") | CL16: =IF($A16="","",IF($AM16<='Study_Setup'!$B$19,1,0)) | CM16: =IF($A16="","",IF(AND($BZ16>='Study_Setup'!$B$16,$CC16>='Study_Setup'!$B$17,$CE16>='Study_Setup'!$B$18,$CL16=1),1,0)) | CN16: =IFERROR(40*MIN(1,$BZ16/'Study_Setup'!$B$16)+25*MIN(1,$CC16/'Study_Setup'!$B$17)+25*MIN(1,$CE16/'Study_Setup'!$B$18)+10*$CL16,"") | CO16: =IF('Pasted_Exports'!BX16<>"",'Pasted_Exports'!BX16,'File_Intake'!BX16) | CP16: =IF('Pasted_Exports'!BY16<>"",'Pasted_Exports'!BY16,'File_Intake'!BY16) | CQ16: =IF('Pasted_Exports'!BZ16<>"",'Pasted_Exports'!BZ16,'File_Intake'!BZ16) | CR16: =IF('Pasted_Exports'!CA16<>"",'Pasted_Exports'!CA16,'File_Intake'!CA16) | CS16: =IF('Pasted_Exports'!CB16<>"",'Pasted_Exports'!CB16,'File_Intake'!CB16) | CT16: =IF('Pasted_Exports'!CC16<>"",'Pasted_Exports'!CC16,'File_Intake'!CC16) | CU16: =IF('Pasted_Exports'!CD16<>"",'Pasted_Exports'!CD16,'File_Intake'!CD16) | CV16: =IF('Pasted_Exports'!CE16<>"",'Pasted_Exports'!CE16,'File_Intake'!CE16) | ... CY16: =IF('Pasted_Exports'!CH16<>"",'Pasted_Exports'!CH16,'File_Intake'!CH16)
